Workbook
Name block.CH4: #REF!
Name block.CO2: #REF!
Name block.CO2: #REF!
Name block.CO2: #REF!
Name block.CO2: #REF!
Name block.CO2: #REF!
Name block.CO2: #REF!
Name block.Fgas: #REF!
Name block.Fgas: #REF!
Name block.Fgas: #REF!
Name block.Fgas: #REF!
Name block.Fgas: #REF!
Name block.Fgas: #REF!
Name block.N2O: #REF!
Name block.N2O: #REF!
Name block.N2O: #REF!
Name block.N2O: #REF!
Name block.N2O: #REF!
Name block.N2O: #REF!
Name CAAGR_tolerance: 200
Name CO2percap: #REF!
Name CO2percap: #REF!
Name CO2percap: #REF!
Name CO2percap: #REF!
Name CO2percap: #REF!
Name CO2percap: #REF!
Name CO2perUSD_GDP: #REF!
Name CO2perUSD_GDP: #REF!
Name CO2perUSD_GDP: #REF!
Name CO2perUSD_GDP: #REF!
Name CO2perUSD_GDP: #REF!
Name CO2perUSD_GDP: #REF!
Name cost_data_2015: '[2]Input costs 2015'!$A$1:$XX$40
Name costdata_notrade: '[2]Input costs 2014'!$A$4:$I$35
Name countries_dropdownlist: [2]Lookups!$A$12:$A$37
Name country_id: #REF!
Name country_id: #REF!
Name country_id: #REF!
Name country_id: #REF!
Name country_id: #REF!
Name country_id: #REF!
Name country_id: #REF!
Name Deflator_Data: [4]GDPdeflator!$E$5:$BK$268
Name Deflator_ID: [4]GDPdeflator!$BN$5:$BN$268
Name Deflator_Year: [4]GDPdeflator!$E$4:$BL$4
Name EDGAR_Country: '[5]Database Emissions EDGAR_FAO'!$B$5:$B$230
Name EDGAR_head: '[5]Database Emissions EDGAR_FAO'!$D$4:$AE$4
Name EDGAR_table: '[5]Database Emissions EDGAR_FAO'!$D$5:$AE$230
Name fac_gdp: '[6]Emissions per GDP (MER)'!$B$1
Name GDP: '[2]Input Population GDP'!$F$38:$U$71
Name GHG: #REF!
Name GHG: #REF!
Name GHG: #REF!
Name GHG: #REF!
Name GHG: #REF!
Name GHG: #REF!
Name GHGpercap: #REF!
Name GHGpercap: #REF!
Name GHGpercap: #REF!
Name GHGpercap: #REF!

Sheet Stephan
A1: Country Code | B1: Country name | C1: Access to electricity (% of population) | D1: International migrant stock (% of population) | E1: Population, total | F1: Control of Corruption: Estimate | G1: Government Effectiveness: Estimate | H1: Political Stability and Absence of Violence/Terrorism: Estimate | I1: Regulatory Quality: Estimate | J1: Rule of Law: Estimate | K1: Voice and Accountability: Estimate | L1: Renewable electricity output (GWh) [4.1.2_REN.ELECTRICITY.OUTPUT] | M1: Renewable electricity share of total electricity output (%) [4.1_SHARE.RE.IN.ELECTRICITY] | N1: Renewable energy consumption (TJ) [3.1_RE.CONSUMPTION] | O1: Renewable energy share of TFEC (%) [2.1_SHARE.TOTAL.RE.IN.TFEC] | P1: Total electricity output (GWh) [4.1.1_TOTAL.ELECTRICITY.OUTPUT] | Q1: Total final energy consumption (TFEC) (TJ) [1.1_TOTAL.FINAL.ENERGY.CONSUM] | R1: CO2 emissions (metric tons per capita)_x | S1: Electricity production from coal sources (% of total) | T1: Forest area (% of land area) | U1: Methane emissions (metric tons of CO2 equivalent per capita) | V1: Net migration | W1: Nitrous oxide emissions (metric tons of CO2 equivalent per capita) | X1: Population density (people per sq. km of land area) | Y1: Annual deforestation (% of change) - (for online table only) | Z1: Coal rents (% of GDP) | AA1: GDP (constant 2015 US$) | AB1: GDP per capita (constant 2015 US$) | AC1: Natural gas rents (% of GDP) | AD1: Oil rents (% of GDP) | AE1: Arable land (% of land area) | AF1: CO2 emissions by sector (Mt CO2 eq) - Building | AG1: CO2 emissions by sector (Mt CO2 eq) - Industrial Processes | AH1: CO2 emissions by sector (Mt CO2 eq) - Transportation | AI1: GHG growth (annual %) | AJ1: Non-CO2 GHG emissions by sector (Mt CO2 eq) - Agriculture | AK1: Non-CO2 GHG emissions by sector (Mt CO2 eq) - Industrial Processes | AL1: Per capita GHG emissions (tons/capita) | AM1: Total GHG emissions by sector (Mt CO2 eq) - Agriculture | AN1: Total GHG emissions by sector (Mt CO2 eq) - Building | AO1: Total GHG emissions by sector (Mt CO2 eq) - Industrial Processes | AP1: Total GHG emissions by sector (Mt CO2 eq) - Transportation | AQ1: Expected Years of Schooling | AR1: Gross National Income (GNI) per capita | AS1: Human Development Index (HDI) | AT1: Life Expectancy | AU1: Mean Years of Schooling | AV1: INFORM Risk Index | AW1: Total GHG Emissions | AX1: TREND_GDP (constant 2015 US$) | AY1: TREND_Mean Years of Schooling | AZ1: TREND_Population density (people per sq. km of land area) | BA1: TREND_Population, total | BB1: Avg reduction percentage from 2022 | BC1: Peaked | BD1: Per capita GHG emissions | BE1: Current Policies (2021 - 2030) | BF1: Residual emissions as % 2021 emissions | BG1: Net-zero target status
A2: ARE | B2: =VLOOKUP($A2,'NZ targets'!$G$13:$BG$238,2,FALSE) -> United Arab Emirates | C2: 100 | D2: 88.404048 | E2: 9441129 | F2: 1.1553365 | G2: 1.2999623 | H2: 0.70078534 | I2: 1.0347807 | J2: 0.83664274 | K2: -1.1272526 | L2: 296 | M2: 0.23240111 | N2: 2869.892 | O2: 0.13710805 | P2: 127366 | Q2: 2093160.9 | R2: 20.252272 | S2: 0 | T2: 4.4677556 | U2: 6.1314669 | V2: -2762 | W2: 0.1970047 | X2: 131.86631 | Y2: -0.26595883 | Z2: 0 | AA2: 3.7086607e+11 | AB2: 37497.581 | AC2: 0.43164407 | AD2: 11.512162 | AE2: 0.68994649 | AF2: 0.8 | AG2: 5.59 | AH2: 37.67 | AI2: -2.44 | AJ2: 2.04 | AK2: 2.87 | AL2: 27.33 | AM2: 2.04 | AN2: 0.8 | AO2: 8.45 | AP2: 37.67 | AQ2: 15.71769 | AR2: 62573.592 | AS2: 0.911 | AT2: 78.7104 | AU2: 12.69403 | AV2: 1.7 | AW2: 295.11026 | AX2: 9.9982192e+09 | AY2: 0.3441696 | AZ2: 1.0813899 | BA2: 75660.006 | BB2: -2.3255814 | BC2: 1 | BD2: =VLOOKUP($A2,'NZ targets'!$G$13:$BG$238,33,FALSE) -> -0.026916159 | BE2: =VLOOKUP($A2,'NZ targets'!$G$13:$BG$238,18,FALSE) -> -13 | BF2: =VLOOKUP($A2,'NZ targets'!$G$13:$BG$238,25,FALSE) -> -8.279541 | BG2: =VLOOKUP($A2,'NZ targets'!$G$13:$BG$238,3,FALSE) -> 3
A3: AUS | B3: =VLOOKUP($A3,'NZ targets'!$G$13:$BG$238,2,FALSE) -> Australia | C3: 100 | D3: 28.21841 | E3: 26005540 | F3: 1.7644895 | G3: 1.5288746 | H3: 0.93357205 | I3: 1.8948933 | J3: 1.5100852 | K3: 1.3194804 | L3: 34405 | M3: 13.637841 | N3: 296838.1 | O3: 9.180503 | P3: 252276 | Q3: 3233353.4 | R3: 14.776137 | S3: 62.871617 | T3: 17.421315 | U3: 5.1262619 | V3: 117929 | W3: 1.9233241 | X3: 3.3392284 | Y3: 0.21483114 | Z3: 0.55413179 | AA3: 1.4909678e+12 | AB3: 58029.516 | AC3: 0.91640161 | AD3: 0.25385847 | AE3: 3.983869 | AF3: 15.1 | AG3: 3.02 | AH3: 99.64 | AI3: -0.61 | AJ3: 159.54 | AK3: 14.42 | AL3: 24.79 | AM3: 159.54 | AN3: 15.1 | AO3: 17.44 | AP3: 99.64 | AQ3: 21.05459 | AR3: 49238.433 | AS3: 0.951 | AT3: 84.5265 | AU3: 12.72682 | AV3: 2.4 | AW3: 571.38211 | AX3: 3.2549747e+10 | AY3: 0.07441249 | AZ3: 0.044636503 | BA3: 329293.78 | BB3: -3.5714286 | BC3: 1 | BD3: =VLOOKUP($A3,'NZ targets'!$G$13:$BG$238,33,FALSE) -> -0.043916955 | BE3: =VLOOKUP($A3,'NZ targets'!$G$13:$BG$238,18,FALSE) -> -60 | BF3: =VLOOKUP($A3,'NZ targets'!$G$13:$BG$238,25,FALSE) -> -63.860982 | BG3: =VLOOKUP($A3,'NZ targets'!$G$13:$BG$238,3,FALSE) -> 4
A4: AUT | B4: =VLOOKUP($A4,'NZ targets'!$G$13:$BG$238,2,FALSE) -> Austria | C4: 100 | D4: 17.465726 | E4: 9041851 | F4: 1.2586194 | G4: 1.4654502 | H4: 0.63799536 | I4: 1.2831998 | J4: 1.7058502 | K4: 1.4087608 | L4: 47243 | M4: 76.490779 | N4: 362355.8 | O4: 34.394992 | P4: 61763 | Q4: 1053513.3 | R4: 6.6326457 | S4: 8.2266082 | T4: 47.294474 | U4: 0.76967401 | V4: 20314 | W4: 0.42164385 | X4: 108.52881 | Y4: -0.053645572 | Z4: 0 | AA4: 3.8651424e+11 | AB4: 43346.432 | AC4: 0.0087652478 | AD4: 0.022711461 | AE4: 16.00921 | AF4: 7.45 | AG4: 1.71 | AH4: 24.76 | AI4: -4.04 | AJ4: 7.41 | AK4: 1.73 | AL4: 7.68 | AM4: 7.41 | AN4: 7.45 | AO4: 3.44 | AP4: 24.76 | AQ4: 16.007959 | AR4: 53618.671 | AS4: 0.916 | AT4: 81.5797 | AU4: 12.25669 | AV4: 1.9 | AW4: 76.743304 | AX4: 3.7895452e+09 | AY4: 0.057440874 | AZ4: 0.7427933 | BA4: 59199.242 | BB4: -5.5555556 | BC4: 1 | BD4: =VLOOKUP($A4,'NZ targets'!$G$13:$BG$238,33,FALSE) -> -0.088718244 | BE4: =VLOOKUP($A4,'NZ targets'!$G$13:$BG$238,18,FALSE) -> -5.2338985 | BF4: =VLOOKUP($A4,'NZ targets'!$G$13:$BG$238,25,FALSE) -> -9.058439 | BG4: =VLOOKUP($A4,'NZ targets'!$G$13:$BG$238,3,FALSE) -> 4
A5: BEL | B5: =VLOOKUP($A5,'NZ targets'!$G$13:$BG$238,2,FALSE) -> Belgium | C5: 100 | D5: 12.283533 | E5: 11685814 | F5: 1.4950486 | G5: 1.2276587 | H5: 0.57566881 | I5: 1.2529552 | J5: 1.3489424 | K5: 1.2926087 | L5: 14466 | M5: 20.800023 | N5: 128345.2 | O5: 9.2016405 | P5: 69548 | Q5: 1394807.8 | R5: 7.3981307 | S5: 6.1080117 | T5: 22.764201 | U5: 0.69107897 | V5: 53428 | W5: 0.3955588 | X5: 382.63524 | Y5: -0.15906384 | Z5: 0 | AA5: 4.6667177e+11 | AB5: 40424.639 | AC5: 3.4458349e-05 | AD5: 0 | AE5: 28.562635 | AF5: 22.41 | AG5: 2.29 | AH5: 25.31 | AI5: 0.46 | AJ5: 9.4 | AK5: 3.06 | AL5: 9.53 | AM5: 9.4 | AN5: 22.41 | AO5: 5.35 | AP5: 25.31 | AQ5: 19.604219 | AR5: 52293.4 | AS5: 0.937 | AT5: 81.8787 | AU5: 12.37568 | AV5: 2.1 | AW5: 114.0322 | AX5: 5.1827842e+09 | AY5: 0.11456469 | AZ5: 1.7752834 | BA5: 55904.479 | BB5: -3.5714286 | BC5: 1 | BD5: =VLOOKUP($A5,'NZ targets'!$G$13:$BG$238,33,FALSE) -> -0.04971585 | BE5: =VLOOKUP($A5,'NZ targets'!$G$13:$BG$238,18,FALSE) -> -0.35387688 | BF5: =VLOOKUP($A5,'NZ targets'!$G$13:$BG$238,25,FALSE) -> -0.61246357 | BG5: =VLOOKUP($A5,'NZ targets'!$G$13:$BG$238,3,FALSE) -> 3
A6: BGD | B6: =VLOOKUP($A6,'NZ targets'!$G$13:$BG$238,2,FALSE) -> Bangladesh | C6: 98.991028 | D6: 0.88375374 | E6: 171186372 | F6: -1.0755273 | G6: -0.7625519 | H6: -1.0923711 | I6: -0.92765892 | J6: -0.60133934 | K6: -0.75266188 | L6: 724 | M6: 1.2268899 | N6: 386058.6 | O6: 34.747069 | P6: 59011 | Q6: 1111053.7 | R6: 0.51064756 | S6: 1.6895155 | T6: 14.468772 | U6: 0.53102074 | V6: -61154 | W6: 0.16770211 | X6: 1301.039 | Y6: 0.17934586 | Z6: 0.01043877 | AA6: 2.6675989e+11 | AB6: 1619.7759 | AC6: 0.20682979 | AD6: 0.0097279476 | AE6: 61.458093 | AF6: 9.82 | AG6: 0.8 | AH6: 12.01 | AI6: 3.07 | AJ6: 88.53 | AK6: 3.18 | AL6: 1.37 | AM6: 88.53 | AN6: 9.82 | AO6: 3.97 | AP6: 12.01 | AQ6: 12.44198 | AR6: 5472.1048 | AS6: 0.661 | AT6: 72.3811 | AU6: 7.3790598 | AV6: 5.7 | AW6: 281.08211 | AX6: 1.3062121e+10 | AY6: 0.26075707 | AZ6: 14.73467 | BA6: 1910366.5 | BB6: -3.5714286 | BC6: 1 | BD6: =VLOOKUP($A6,'NZ targets'!$G$13:$BG$238,33,FALSE) | BE6: =VLOOKUP($A6,'NZ targets'!$G$13:$BG$238,18,FALSE) -> 8.2258266 | BF6: =VLOOKUP($A6,'NZ targets'!$G$13:$BG$238,25,FALSE) -> 7.6369218 | BG6: =VLOOKUP($A6,'NZ targets'!$G$13:$BG$238,3,FALSE) -> 1
A7: BGR | B7: =VLOOKUP($A7,'NZ targets'!$G$13:$BG$238,2,FALSE) -> Bulgaria | C7: 99.8 | D7: 1.4281964 | E7: 6465097 | F7: -0.15789711 | G7: -0.27079985 | H7: 0.24625206 | I7: 0.32068691 | J7: -0.10721157 | K7: 0.28520486 | L7: 8768 | M7: 17.988593 | N7: 69034.96 | O7: 17.650078 | P7: 48742 | Q7: 391131.19 | R7: 4.9232804 | S7: 46.206557 | T7: 35.980103 | U7: 1.0067034 | V7: -9902 | W7: 0.62427463 | X7: 63.354302 | Y7: -0.83439604 | Z7: 0.071455114 | AA7: 5.4923718e+10 | AB7: 7920.9113 | AC7: 0.0049703973 | AD7: 0.01300645 | AE7: 32.166544 | AF7: 1.02 | AG7: 1.24 | AH7: 9.44 | AI7: -13.82 | AJ7: 5.26 | AK7: 1.37 | AL7: 2.78 | AM7: 5.26 | AN7: 1.02 | AO7: 2.6 | AP7: 9.44 | AQ7: 13.89729 | AR7: 23078.956 | AS7: 0.795 | AT7: 71.798 | AU7: 11.41318 | AV7: 2.7 | AW7: 68.413545 | AX7: 1.0046248e+09 | AY7: 0.056774055 | AZ7: -0.44229846 | BA7: -68790.909 | BB7: -2.3255814 | BC7: 1 | BD7: =VLOOKUP($A7,'NZ targets'!$G$13:$BG$238,33,FALSE) | BE7: =VLOOKUP($A7,'NZ targets'!$G$13:$BG$238,18,FALSE) -> -9.4482011 | BF7: =VLOOKUP($A7,'NZ targets'!$G$13:$BG$238,25,FALSE) -> -10.72419 | BG7: =VLOOKUP($A7,'NZ targets'!$G$13:$BG$238,3,FALSE) -> 1
A8: BHR | B8: =VLOOKUP($A8,'NZ targets'!$G$13:$BG$238,2,FALSE) -> Bahrain | C8: 100 | D8: 51.126785 | E8: 1472233 | F8: 0.13938564 | G8: 0.64042491 | H8: -0.4070285 | I8: 0.97063351 | J8: 0.43882862 | K8: -1.4175618 | L8: 0 | M8: 0 | N8: 0 | O8: 0 | P8: 28484 | Q8: 191733.46 | R8: 21.976908 | S8: 0 | T8: 0.91139241 | U8: 11.940307 | V8: -48716 | W8: 0.11617056 | X8: 1852.2342 | Y8: -3.2753404 | Z8: 0 | AA8: 3.3258424e+10 | AB8: 19545.579 | AC8: 1.3230688 | AD8: 7.3591311 | AE8: 2.0382166 | AF8: 0.27 | AG8: 0.56 | AH8: 3.85 | AI8: 2.1 | AJ8: 0.05 | AK8: 3.31 | AL8: 31.19 | AM8: 0.05 | AN8: 0.27 | AO8: 3.87 | AP8: 3.85 | AQ8: 16.29756 | AR8: 39497.248 | AS8: 0.875 | AT8: 78.7605 | AU8: 11.04659 | AV8: 1.4 | AW8: 69.976212 | AX8: 9.0491907e+08 | AY8: 0.32702732 | AZ8: 34.387925 | BA8: 23155.63 | BB8: -1.8867925 | BC8: 1 | BD8: =VLOOKUP($A8,'NZ targets'!$G$13:$BG$238,33,FALSE) -> -0.02220396 | BE8: =VLOOKUP($A8,'NZ targets'!$G$13:$BG$238,18,FALSE) -> -0.0248 | BF8: =VLOOKUP($A8,'NZ targets'!$G$13:$BG$238,25,FALSE) -> -0.031253049 | BG8: =VLOOKUP($A8,'NZ targets'!$G$13:$BG$238,3,FALSE) -> 2
A9: CAN | B9: =VLOOKUP($A9,'NZ targets'!$G$13:$BG$238,2,FALSE) -> Canada | C9: 100 | D9: 21.801664 | E9: 38929902 | F9: 1.6585798 | G9: 1.5670705 | H9: 0.77281404 | I9: 1.6770928 | J9: 1.5662202 | K9: 1.4349684 | L9: 422643 | M9: 63.01145 | N9: 1587094 | O9: 22.025359 | P9: 670740 | Q9: 7205757.6 | R9: 13.599375 | S9: 9.8364493 | T9: 39.470128 | U9: 2.6348554 | V9: 195181 | W9: 1.2387219 | X9: 4.3495054 | Y9: 0.014063977 | Z9: 0.053023333 | AA9: 1.6074025e+12 | AB9: 42258.691 | AC9: 0.037249734 | AD9: 1.0879346 | AE9: 4.2646385 | AF9: 75.68 | AG9: 6.75 | AH9: 192.11 | AI9: 2.37 | AJ9: 58.95 | AK9: 14.88 | AL9: 20.6 | AM9: 58.95 | AN9: 75.68 | AO9: 21.64 | AP9: 192.11 | AQ9: 16.396259 | AR9: 46807.986 | AS9: 0.936 | AT9: 82.6565 | AU9: 13.834427 | AV9: 2.4 | AW9: 756.81011 | AX9: 2.49098e+10 | AY9: 0.028846842 | AZ9: 0.050256576 | BA9: 428256.61 | BB9: -3.5714286 | BC9: 1 | BD9: =VLOOKUP($A9,'NZ targets'!$G$13:$BG$238,33,FALSE) -> -0.039599481 | BE9: =VLOOKUP($A9,'NZ targets'!$G$13:$BG$238,18,FALSE) -> -100 | BF9: =VLOOKUP($A9,'NZ targets'!$G$13:$BG$238,25,FALSE) -> -28.496771 | BG9: =VLOOKUP($A9,'NZ targets'!$G$13:$BG$238,3,FALSE) -> 4
A10: CHE | B10: =VLOOKUP($A10,'NZ targets'!$G$13:$BG$238,2,FALSE) -> Switzerland | C10: 100 | D10: 29.386686 | E10: 8775760 | F10: 2.0093138 | G10: 2.0499489 | H10: 1.1611397 | I10: 1.620113 | J10: 1.7518067 | K10: 1.6155596 | L10: 41111 | M10: 62.197982 | N10: 195365.5 | O10: 25.291984 | P10: 66097 | Q10: 772440.4 | R10: 4.0420728 | S10: 0 | T10: 32.208603 | U10: 0.5759601 | V10: 53786 | W10: 0.27745615 | X10: 220.31454 | Y10: -0.32739763 | Z10: 0 | AA10: 7.4002624e+11 | AB10: 85685.29 | AC10: 0 | AD10: 0 | AE10: 10.118463 | AF10: 11.34 | AG10: 1.76 | AH10: 15.82 | AI10: -2.62 | AJ10: 5.54 | AK10: 1.67 | AL10: 5.14 | AM10: 5.54 | AN10: 11.34 | AO10: 3.42 | AP10: 15.82 | AQ10: 16.500299 | AR10: 66933.005 | AS10: 0.962 | AT10: 83.9872 | AU10: 13.85966 | AV10: 1.4 | AW10: 45.56382 | AX10: 1.1788789e+10 | AY10: 0.047105968 | AZ10: 1.9829354 | BA10: 74158.636 | BB10: -3.5714286 | BC10: 1 | BD10: =VLOOKUP($A10,'NZ targets'!$G$13:$BG$238,33,FALSE) -> -0.048161487 | BE10: =VLOOKUP($A10,'NZ targets'!$G$13:$BG$238,18,FALSE) -> -1.4340403 | BF10: =VLOOKUP($A10,'NZ targets'!$G$13:$BG$238,25,FALSE) -> -1.4849326 | BG10: =VLOOKUP($A10,'NZ targets'!$G$13:$BG$238,3,FALSE) -> 4
A11: CHL | B11: =VLOOKUP($A11,'NZ targets'!$G$13:$BG$238,2,FALSE) -> Chile | C11: 100 | D11: 2.6155132 | E11: 19603733 | F11: 0.96828014 | G11: 0.54677397 | H11: 0.11857886 | I11: 0.97841114 | J11: 0.69040066 | K11: 0.97297513 | L11: 32872 | M11: 43.604335 | N11: 259606.8 | O11: 24.882554 | P11: 75387 | Q11: 1043328.6 | R11: 4.3951511 | S11: 37.144335 | T11: 24.657473 | U11: 0.61115767 | V11: 98439 | W11: 0.34193389 | X11: 26.217007 | Y11: -0.75873432 | Z11: 0.0071161044 | AA11: 2.4641299e+11 | AB11: 12890.264 | AC11: 0.011224695 | AD11: 0.017901358 | AE11: 1.6098836 | AF11: 6.58 | AG11: 0.88 | AH11: 28.33 | AI11: -1.89 | AJ11: 10.65 | AK11: 3.15 | AL11: 2.76 | AM11: 10.65 | AN11: 6.58 | AO11: 4.03 | AP11: 28.33 | AQ11: 16.7313 | AR11: 24563.245 | AS11: 0.855 | AT11: 78.9435 | AU11: 10.934966 | AV11: 3.2 | AW11: 137.01125 | AX11: 4.4544707e+09 | AY11: 0.13699494 | AZ11: 0.33774918 | BA11: 253560.3 | BB11: -2.3255814 | BC11: 1 | BD11: =VLOOKUP($A11,'NZ targets'!$G$13:$BG$238,33,FALSE) -> -0.028594465 | BE11: =VLOOKUP($A11,'NZ targets'!$G$13:$BG$238,18,FALSE) -> 65 | BF11: =VLOOKUP($A11,'NZ targets'!$G$13:$BG$238,25,FALSE) -> -62.58523 | BG11: =VLOOKUP($A11,'NZ targets'!$G$13:$BG$238,3,FALSE) -> 4
A12: CHN | B12: =VLOOKUP($A12,'NZ targets'!$G$13:$BG$238,2,FALSE) -> China | C12: 100 | D12: 0.071076396 | E12: 1412175000 | F12: 0.015970249 | G12: 0.49503201 | H12: -0.44107363 | I12: -0.41841763 | J12: -0.041443985 | K12: -1.6095749 | L12: 1398321 | M12: 23.926817 | N12: 9084482 | O12: 12.413353 | P12: 5844158 | Q12: 73183147 | R12: 7.7561379 | S12: 70.309427 | T12: 23.631528 | U12: 0.84068116 | V12: -33649 | W12: 0.38049763 | X12: 150.43975 | Y12: -1.0921141 | Z12: 0.35006509 | AA12: 1.461654e+13 | AB12: 10358.259 | AC12: 0.10814925 | AD12: 0.25510718 | AE12: 12.676591 | AF12: 542.13 | AG12: 782 | AH12: 917.02 | AI12: 2.61 | AJ12: 672.87 | AK12: 384.29 | AL12: 8.4 | AM12: 672.87 | AN12: 542.13 | AO12: 1166.29 | AP12: 917.02 | AQ12: 14.236115 | AR12: 17504.4 | AS12: 0.768 | AT12: 78.2107 | AU12: 7.6001184 | AV12: 3 | AW12: 15684.627 | AX12: 7.3760223e+11 | AY12: 0.083395467 | AZ12: 0.71986065 | BA12: 5736515.2 | BB12: -1.8867925 | BC12: 1 | BD12: =VLOOKUP($A12,'NZ targets'!$G$13:$BG$238,33,FALSE) -> -0.020453535 | BE12: =VLOOKUP($A12,'NZ targets'!$G$13:$BG$238,18,FALSE) -> -1211.5892 | BF12: =VLOOKUP($A12,'NZ targets'!$G$13:$BG$238,25,FALSE) -> -1377.2091 | BG12: =VLOOKUP($A12,'NZ targets'!$G$13:$BG$238,3,FALSE) -> 3
A13: COD | B13: =VLOOKUP($A13,'NZ targets'!$G$13:$BG$238,2,FALSE) -> Congo, Democratic Republic | C13: 20.768187 | D13: 0.70624628 | E13: 99010212 | F13: -1.544474 | G13: -1.7459201 | H13: -1.9777462 | I13: -1.4760695 | J13: -1.6724339 | K13: -1.1836931 | L13: 8926 | M13: 99.821069 | N13: 862513.8 | O13: 95.8177 | P13: 8942 | Q13: 900161.25 | R13: 0.032584781 | S13: 0 | T13: 55.161493 | U13: 0.38430795 | V13: -1643 | W13: 0.16112069 | X13: 42.299075 | Y13: 0.20082871 | Z13: 0 | AA13: 4.5259707e+10 | AB13: 505.34834 | AC13: 0 | AD13: 0.50031777 | AE13: 5.9447299 | AF13: 0 | AG13: 0.08 | AH13: 2.07 | AI13: -0.66 | AJ13: 25.98 | AK13: 2.1 | AL13: 8.11 | AM13: 25.98 | AN13: 0 | AO13: 2.18 | AP13: 2.07 | AQ13: 9.8178645 | AR13: 1076.0988 | AS13: 0.479 | AT13: 59.193 | AU13: 7.0186965 | AV13: 7.7 | AW13: 61.635094 | AX13: 1.9707114e+09 | AY13: 0.14352156 | AZ13: 1.2225697 | BA13: 2837421.5 | BB13: -2.3255814 | BC13: 0 | BD13: =VLOOKUP($A13,'NZ targets'!$G$13:$BG$238,33,FALSE) | BE13: =VLOOKUP($A13,'NZ targets'!$G$13:$BG$238,18,FALSE) -> 214.60858 | BF13: =VLOOKUP($A13,'NZ targets'!$G$13:$BG$238,25,FALSE) -> 180.17104 | BG13: =VLOOKUP($A13,'NZ targets'!$G$13:$BG$238,3,FALSE) -> 1
... A77: ZMB | B77: =VLOOKUP($A77,'NZ targets'!$G$13:$BG$238,2,FALSE) -> Zambia | C77: 46.685116 | D77: 0.78902565 | E77: 20017675 | F77: -0.52919984 | G77: -0.65823275 | H77: 0.10231356 | I77: -0.52905792 | J77: -0.51915401 | K77: -0.089141272 | L77: 13035 | M77: 96.993824 | N77: 301679.8 | O77: 87.985452 | P77: 13439 | Q77: 342874.64 | R77: 0.40190271 | S77: 0 | T77: 60.03015 | U77: 0.81619743 | V77: 9015 | W77: 0.65319531 | X77: 26.195032 | Y77: 0.33348405 | Z77: 0.14289322 | AA77: 2.3418946e+10 | AB77: 1273.8796 | AC77: 0 | AD77: 0 | AE77: 5.1117179 | AF77: 0.13 | AG77: 1.05 | AH77: 2.03 | AI77: -0.68 | AJ77: 24.45 | AK77: 0.59 | AL77: 5.37 | AM77: 24.46 | AN77: 0.13 | AO77: 1.64 | AP77: 2.03 | AQ77: 10.92876 | AR77: 3217.7677 | AS77: 0.565 | AT77: 61.2234 | AU77: 7.1870915 | AV77: 3.9 | AW77: 30.330585 | AX77: 7.1781519e+08 | AY77: 0.092849732 | AZ77: 0.70856464 | BA77: 533121.38 | BB77: -3.5714286 | BC77: 1 | BD77: =VLOOKUP($A77,'NZ targets'!$G$13:$BG$238,33,FALSE) | BE77: =VLOOKUP($A77,'NZ targets'!$G$13:$BG$238,18,FALSE) -> -23.398434 | BF77: =VLOOKUP($A77,'NZ targets'!$G$13:$BG$238,25,FALSE) -> -28.037488 | BG77: =VLOOKUP($A77,'NZ targets'!$G$13:$BG$238,3,FALSE) -> 1

Sheet NZ targets
F1: Target types | G1: Column1 | H1: Type | I1: Number of countries | J1: Emissions share in 2018 | K1: https://eciu.net/netzerotracker | L1: Target types | M1: Number of countries | N1: Emissions share in 2018 | AN1: Source:
F2: Achieved (self-declared) | H2: 5 | I2: =COUNTIF(I$13:I$239,$H2) -> 6 | J2: =SUMIF($I$13:$I$236,5,$J$13:$J$236)/$J$261 -> 0.00057882977 | L2: Achieved, Policy documents, Proposed, Law | M2: =SUM(I2:I5) -> 96 | N2: =SUM(J2:J5) -> 0.84592132 | W2: Residual emissions LULUCF | AN2: IIASA calculations (under development) based on inventory data and national communications. The database is almost ready and will be documented later.
F3: In Law | H3: 4 | I3: =COUNTIF(I$13:I$239,$H3) -> 27 | J3: =(SUMIF($I$13:$I$236,4,$J$13:$J$236))/$J$261 -> 0.23567347 | P3: =N2+N3 -> 0.84592132 | W3: Current policies scenarios | AN3: Nascimento, L., et al., Greenhouse gas mitigation scenarios for major emitting countries. Analysis of current climate policies and mitigation commitments: 2023 Update, 2023: NewClimate Institute (Cologne, Germany), PBL (The Hague, the Netherlands), IIASA (Austria), https://newclimate.org/resources/publications/emissions-scenarios-for-major-economies-2023-update.
F4: In policy document | H4: 3 | I4: =COUNTIF(I$13:I$239,$H4) -> 51 | J4: =SUMIF($I$13:$I$236,3,$J$13:$J$236)/$J$261 -> 0.48575044 | L4: Net zero-target Under Discussion | M4: =I6-M3 -> 55 | N4: =J6-N3 -> 0.0604576 | W4: 2021 emissions | AG4: Commentaar index | AN4: National inventory data, as reported in : Nascimento et al. (2013) for the major emitting countries, and for the other countries
F5: Declaration / pledge | H5: 2 | I5: =COUNTIF(I$13:I$239,$H5) -> 12 | J5: =(SUMIF($I$13:$I$236,2,$J$13:$J$236)+J238)/$J$261 -> 0.12391858 | L5: Climate ambition alliance * | M5: =I7 -> 0 | N5: =J7 -> 0 | AG5: =1000000000*(W20-AC20)/(2050-2022)/BA20 -> -219.55181 | AN5: Gütschow, J. and M. Pflüger, The PRIMAP-hist national historical emissions time series v2.5 (1750-2022). zenodo, 2023.
F6: Proposed / in discussion | H6: 1 | I6: =COUNTIF(I$13:I$239,$H6) -> 55 | J6: =SUMIF($I$13:$I$236,1,$J$13:$J$236)/$J$261 -> 0.0604576 | L6: Countries with no zero target | M6: =I8 -> 74 | N6: =J8 -> 0.090564902 | Q6: * https://unfccc.int/news/climate-ambition-alliance-nations-renew-their-push-to-upscale-action-by-2020-and-achieve-net-zero | W6: NDC targets | AN6: den Elzen, M.G.J., et al., The impact of policy and model uncertainties on emissions projections of the Paris Agreement pledges. Environmental Research Letters, 2023. 18(5): p. 054026.
F7: Climate ambition alliance * | H7: -1 | I7: =COUNTIF(I$13:I$239,$H7) -> 0 | J7: =SUMIF($I$13:$I$236,-1,$J$13:$J$236)/$J$261 -> 0 | L7: Int bunker emissions, remaining LULUCF | N7: =(J243+J244)/J261 -> 0.0030561825 | Q7: https://www.climatechangenews.com/2020/09/17/countries-net-zero-climate-goal/ | AI7: World average Penalty
F8: No target | H8: 0 | I8: =COUNTIF(I$13:I$239,$H8) -> 74 | J8: =SUMIF($I$13:$I$236,0,$J$13:$J$236)/$J$261 -> 0.090564902 | L8: Total | M8: =SUM(M2:M7) -> 225 | N8: =SUM(N2:N7) -> 1 | AI8: 7
F9: EU is only counted for the EU as a whole | H9: INPUT in "input site" | I9: =SUM(I2:I8) -> 225 | J9: =SUM(J2:J8) -> 0.99694382 | L9: Total (EU in MSs) | M9: =M8+27 -> 252 | T9: Nascimento et al | W9: Assumed at least zero residual emissions (not negative) | AF9: Adjust for Incl/Excl LULUCF | AI9: Penalty | AW9: Excl LULUCF | BA9: Equity | BE9: Rogelj et al
G10: =1 -> 1 | H10: =G10+1 -> 2 | I10: =H10+1 -> 3 | J10: =I10+1 -> 4 | K10: =J10+1 -> 5 | L10: =K10+1 -> 6 | M10: =L10+1 -> 7 | N10: =M10+1 -> 8 | O10: =N10+1 -> 9 | ... W10: =V10+1 -> 17 | AF10: Important for Canada, etc. | AI10: -10 | AL10: =W10+1 -> 18 | AN10: =AL10+1 -> 19 | AQ10: =AN10+1 -> 20 | AR10: =AQ10+1 -> 21 | AS10: =AR10+1 -> 22 | AT10: =AS10+1 -> 23 | AU10: =AT10+1 -> 24 | AV10: =AU10+1 -> 25 | BA10: =AV10+1 -> 26 | BB10: =BA10+1 -> 27 | BC10: =BB10+1 -> 28 | BD10: =BC10+1 -> 29 | BE10: =BD10+1 -> 30 | BF10: =BE10+1 -> 31 | BG10: =BF10+1 -> 32 | BH10: Rogelj | BI10: EGR 2023 | BN10: Smith etal
A11: Rogelj analysis | B11: G20 | C11: ISO | D11: VSF nr | E11: Region code | F11: LULUCF | G11: ISO | H11: (Mt CO2 equivalent) | I11: Net-zero target status | J11: 2021 emissions | K11: Current policies | L11: Net-zero targets if available (alternative Current policies) | M11: 2 Degree & net-zero targets | N11: 2 degree scenario | O11: NZ target year | P11: Difference 2Degree - LTS | Q11: 1.5 Degree & net-zero targets | R11: 1.5 degree scenario | S11: Reaching net-zero | T11: Country | U11: Net zero year | V11: NZ GHG year | W11: residual LULUCF emissions in 2050 | X11: LULUCF emis-sions NZ | Y11: LULUCF NDC uncond | Z11: LULUCF NDC cond | AA11: GHG emissions incl LULUCF | AB11: LULUCF emis-sions in 20213 | AC11: GHG emissions excl LULUCF | AD11: Current Policies 2030 incl LULUCF | AE11: LULUCF CurPol 2030 | AF11: Current Policies 2030 excl LULUCF | AG11: Formule Stephan | AH11: (A) Formule Peak | AI11: Penalty (1) | AJ11: Formule no Peak (2) | AK11: (B) Formule no Peak | AL11: Current Policies (2021 - 2030) | AM11: Reduction rate CurPol to NZ target | AN11: Reduction rate 2021 to NZ target2 | AO11: Reduction rate NDC to NZ target | AP11: Maximum inventory data | AQ11: Peak revised | AR11: Residual emissions as % 2021 emissions | AS11: 2030 unconditional NDCs | AT11: 2030 unconditional NDCs2 | AU11: 2030 conditional NDCs | AV11: 2030 conditional NDCs2 | AW11: 2031 conditional NDCs2 | AX11: 2032 conditional NDCs2 | AY11: 2033 conditional NDCs2 | AZ11: 2034 conditional NDCs2 | BA11: Population | BB11: Income | BC11: Incomeper capita | BD11: Emissions per capita | BE11: Legally binding | BF11: Published plan (BOLD: manually coded) | BG11: CurPol 10% below | BH11: Confidence assessment | BI11: Confidence assessment2 | BJ11: Current Policies (2021 - 2030)2 | BK11: Reduction rate CurPol to NZ target3 | BL11: Reduction rate 2021 to NZ target24 | BM11: Reduction rate NDC to NZ target5 | BN11: Low residual LULUCF | BO11: High residual LULUCF | BP11: Low res. CDR | BQ11: High res. CDR | BR11: (Mt CO2 equivalent)2 | BT11: Check
A12: Number | B12: Number | C12: Number | D12: Number | E12: Number | F12: Excl/Incl | G12: Code | H12: Country name | I12: Net zero target | J12: 2021 | K12: 2050 | L12: 2050 | M12: NZT -year | N12: 2050 | O12: 2050 | P12: 2050 | Q12: 2050 | R12: 2050 | S12: Net-zero date | T12: =Table12[[#This Row],[(Mt CO2 equivalent)]] -> Country name | U12: Net zero year | V12: NZ GHG year | W12: residual LULUCF emissions in 2050 | X12: LULUCF emissions NZ | Y12: uncod LULUCF emissions 2030 | Z12: cond LULUCF emissions 2030 | AA12: GHG emissions incl LULUCF 2021 | AB12: LULUCF emissions 2021 | AC12: GHG emissions excl LULUCF 2021 | AD12: Current Policies 2030 incl LULUCF | AE12: 2030 median | AF12: Current Policies 2030 excl LULUCF | AG12: tCO2e/cap | AH12: tCO2e/cap | AI12: tCO2e/cap | AJ12: tCO2e/cap | AK12: tCO2e/cap | AL12: Current Policies (2021 - 2030) | AM12: Reduction rate CurPol to NZ target | AN12: Reduction rate 2021 to NZ target2 | AO12: Reduction rate NDC to NZ target | AP12: MtCO2e | AQ12: =IF(Table12[[#This Row],[Current Policies 2030 incl LULUCF]]>Table12[[#This Row],[Maximum inventory data]],"No","Yes") -> Yes | AR12: %-share in 2021 | AS12: ='input site'!BE12 -> Low | AT12: ='input site'!BF12 -> High | AU12: ='input site'!BG12 -> Low | AV12: 2034 conditional NDCs2 incl | AW12: 2031 conditional NDCs2 | AX12: 2032 conditional NDCs2 | AY12: 2033 conditional NDCs2 | AZ12: 2034 conditional NDCs2 | BA12: 2022 | BB12: 2022 | BC12: 2022 | BD12: 2022 | BJ12: %/yr | BK12: %/yr | BL12: %/yr | BM12: %/yr | BR12: Country name
A13: 0 | B13: 0 | C13: 4 | D13: 1 | E13: 25 | F13: ='input site'!M13 -> excl | G13: AFG | H13: Afghanistan | I13: =VLOOKUP($G13,'NZT data'!$B$3:$C$200,2,FALSE) -> 1 | J13: ='input site'!AS13 -> 48.204461 | K13: ='input site'!BS13 -> 58.63732 | L13: =IF(I13>=1,O13,K13) -> 0 | M13: =IF(I13>=1,O13,N13) -> 0 | N13: ='input site'!EV13 -> 28.988983 | Q13: =IF(I13>=1,O13,R13) -> 0 | R13: ='[5]input site'!CN13 -> 9.2522941 | S13: 2050 | T13: =Table12[[#This Row],[(Mt CO2 equivalent)]] -> Afghanistan | U13: =VLOOKUP($G13,'NZT data'!$B$3:$F$200,4,FALSE) -> 2110 | V13: =VLOOKUP($G13,'NZT data'!$B$3:$F$200,5,FALSE) -> 2125 | W13: =-IF('LUC NGHGI'!EC3="",MIN('LUC NGHGI'!DW3,0.1),MIN('LUC NGHGI'!EC3,0.1)) -> -0.1 | X13: ='LUC NGHGI'!EC3 -> 0 | Y13: ='LUC NGHGI'!DY3 -> 0 | Z13: ='LUC NGHGI'!DZ3 -> 0 | AA13: =Table12[[#This Row],[2021 emissions]] -> 48.204461 | AB13: ='LUC NGHGI'!DW3 -> 9.43107 | AC13: =IF(F13="incl",Table12[[#This Row],[GHG emissions incl LULUCF]]-Table12[[#This Row],[LULUCF emis-sions in 20213]],Table12[[#This Row],[GHG emissions incl LULUCF]]) -> 48.204461 | AD13: ='input site'!BS13 -> 58.63732 | AE13: ='LUC NGHGI'!EH3 -> 0 | AF13: =IF(F13="incl",Table12[[#This Row],[Current Policies 2030 incl LULUCF]]-Table12[[#This Row],[LULUCF CurPol 2030]],Table12[[#This Row],[Current Policies 2030 incl LULUCF]]) -> 58.63732 | AG13: =IF(Table12[[#This Row],[Net-zero target status]]<=1,"",IF(Table12[[#This Row],[NZ GHG year]]="","",1000000000*(Table12[[#This Row],[residual LULUCF emissions in 2050]]-Table12[[#This Row],[GHG emissions excl LULUCF]])/(Table12[[#This Row],[NZ GHG year]]-2021)/Table12[[#This Row],[Population]])) | AH13: =IF(Table12[[#This Row],[Peak revised]]="Yes",IF(Table12[[#This Row],[Net-zero target status]]<=1,"",IF(Table12[[#This Row],[NZ GHG year]]="","",1000000000*(Table12[[#This Row],[residual LULUCF emissions in 2050]]-Table12[[#This Row],[GHG emissions excl LULUCF]])/(Table12[[#This Row],[NZ GHG year]]-2021)/Table12[[#This Row],[Population]])),"") | AI13: =MAX(0,(1000000*(Table12[[#This Row],[Current Policies 2030 excl LULUCF]]/2+Table12[[#This Row],[GHG emissions excl LULUCF]]/2)/Table12[[#This Row],[Population]]-$AI$8)*10)*$AI$10 -> 0 | AJ13: =IF(Table12[[#This Row],[Peak revised]]="No",IF(Table12[[#This Row],[Net-zero target status]]<=1,"",IF(Table12[[#This Row],[NZ GHG year]]="","",1000000000*(Table12[[#This Row],[residual LULUCF emissions in 2050]]-Table12[[#This Row],[Current Policies 2030 excl LULUCF]])/(Table12[[#This Row],[NZ GHG year]]-2021)/Table12[[#This Row],[Population]])),"") | AK13: =IF(Table12[[#This Row],[Formule no Peak (2)]]="","",Table12[[#This Row],[Penalty (1)]]+Table12[[#This Row],[Formule no Peak (2)]]) | AL13: =(Table12[[#This Row],[Current Policies 2030 excl LULUCF]]-Table12[[#This Row],[GHG emissions excl LULUCF]])/(2030-2021)/Table12[[#This Row],[GHG emissions excl LULUCF]] -> 0.024047702 | AM13: =IF(Table12[[#This Row],[Net-zero target status]]<=1,"",IF(Table12[[#This Row],[NZ GHG year]]="","",(Table12[[#This Row],[residual LULUCF emissions in 2050]]-Table12[[#This Row],[Current Policies 2030 excl LULUCF]])/(Table12[[#This Row],[NZ GHG year]]-2030)/Table12[[#This Row],[Current Policies 2030 excl LULUCF]])) | AN13: =IF(Table12[[#This Row],[Net-zero target status]]<=1,"",IF(Table12[[#This Row],[NZ GHG year]]="","",(Table12[[#This Row],[residual LULUCF emissions in 2050]]-Table12[[#This Row],[GHG emissions excl LULUCF]])/(Table12[[#This Row],[NZ GHG year]]-2021)/Table12[[#This Row],[GHG emissions excl LULUCF]])) | AO13: =IF(Table12[[#This Row],[Net-zero target status]]<=1,"",IF(Table12[[#This Row],[NZ GHG year]]="","",(Table12[[#This Row],[residual LULUCF emissions in 2050]]-Table12[[#This Row],[2030 conditional NDCs]])/(Table12[[#This Row],[NZ GHG year]]-2030)/Table12[[#This Row],[2030 conditional NDCs]])) | AP13: =MAX('input site'!AH13:AS13) -> 48.204461 | AQ13: =IF(Table12[[#This Row],[Current Policies 2030 incl LULUCF]]>Table12[[#This Row],[Maximum inventory data]],"No","Yes") -> No | AR13: =IF(Table12[[#This Row],[Net-zero target status]]>=1.5,Table12[[#This Row],[residual LULUCF emissions in 2050]]/Table12[[#This Row],[GHG emissions excl LULUCF]],"") | AU13: ='input site'!BG13 -> 42.283763 | AV13: ='input site'!BH13 -> 42.283763 | AW13: =IF(Table12[[#This Row],[2030 unconditional NDCs]]="","",IF(F13="incl",Table12[[#This Row],[2030 unconditional NDCs]]-Table12[[#This Row],[LULUCF NDC uncond]],Table12[[#This Row],[2030 unconditional NDCs]])) | AX13: =IF(Table12[[#This Row],[2030 unconditional NDCs2]]="","",IF(F13="incl",Table12[[#This Row],[2030 unconditional NDCs2]]-Table12[[#This Row],[LULUCF NDC uncond]],Table12[[#This Row],[2030 unconditional NDCs2]])) | AY13: =IF(Table12[[#This Row],[2030 conditional NDCs]]="","",IF(F13="incl",Table12[[#This Row],[2030 conditional NDCs]]-Table12[[#This Row],[LULUCF NDC cond]],Table12[[#This Row],[2030 conditional NDCs]])) -> 42.283763 | AZ13: =IF(Table12[[#This Row],[2030 conditional NDCs2]]="","",IF(F13="incl",Table12[[#This Row],[2030 conditional NDCs2]]-Table12[[#This Row],[LULUCF NDC cond]],Table12[[#This Row],[2030 conditional NDCs2]])) -> 42.283763 | BA13: =VLOOKUP($G13,'Population90 20'!$C$6:$AU$231,37,FALSE) -> 40754388 | BB13: =VLOOKUP($G13,'Overview GDP (PPP)'!$C$6:$AI$231,33,FALSE) -> 64483801 | BC13: =Table12[[#This Row],[Income]]/Table12[[#This Row],[Population]] -> 1.5822542 | BD13: =Table12[[#This Row],[GHG emissions excl LULUCF]]*1000000/Table12[[#This Row],[Population]] -> 1.1828042 | BE13: =VLOOKUP($G13,EGR2023_MASTER!$B$4:$S$38,14,FALSE) -> #N/A | BF13: =VLOOKUP($G13,EGR2023_MASTER!$B$4:$S$38,15,FALSE) -> #N/A | BG13: =VLOOKUP($G13,EGR2023_MASTER!$B$4:$S$38,16,FALSE) -> #N/A | BH13: =IF(AND(BE13="Y",AND(BF13="credible",BG13="Y")),"higher",IF(BG13="Y","lower",IF(AND(BG13="N",OR(BE13="Y",BF13="credible")),"lower","much lower"))) -> #N/A | BI13: =IF(AND($BF13="credible",BG13="Y"),"stronger","weak") -> #N/A | BJ13: =(Table12[[#This Row],[Current Policies 2030 excl LULUCF]]/Table12[[#This Row],[GHG emissions excl LULUCF]])^(1/(2030-2021))-1 -> 0.022007535 | BK13: =IF(Table12[[#This Row],[Net-zero target status]]<=1,"",IF(Table12[[#This Row],[NZ GHG year]]="","",((MAX(Table12[[#This Row],[residual LULUCF emissions in 2050]],0.1)/Table12[[#This Row],[Current Policies 2030 excl LULUCF]])^(1/(Table12[[#This Row],[NZ GHG year]]-2021))-1))) | BL13: =IF(Table12[[#This Row],[Net-zero target status]]<=1,"",IF(Table12[[#This Row],[NZ GHG year]]="","",((MAX(Table12[[#This Row],[residual LULUCF emissions in 2050]],0.1)/Table12[[#This Row],[GHG emissions excl LULUCF]])^(1/(Table12[[#This Row],[NZ GHG year]]-2021))-1))) | BM13: =IF(Table12[[#This Row],[Net-zero target status]]<=1,"",IF(Table12[[#This Row],[NZ GHG year]]="","",((MAX(Table12[[#This Row],[residual LULUCF emissions in 2050]],0.1)/AVERAGE(Table12[[#This Row],[2030 conditional NDCs]:[2030 conditional NDCs2]]))^(1/(Table12[[#This Row],[NZ GHG year]]-2021))-1))) | BR13: Afghanistan | BT13: =IF(Table12[[#This Row],[Reduction rate 2021 to NZ target2]]="","",J13*(1+AN13)^(Table12[[#This Row],[NZ GHG year]]-2021))
A14: 0 | B14: 0 | C14: 8 | D14: 2 | E14: 12 | F14: ='input site'!M14 -> excl | G14: ALB | H14: Albania | I14: 0 | J14: ='input site'!AS14 -> 10.422791 | K14: ='input site'!BS14 -> 5.3405672 | L14: =IF(I14>=1,O14,K14) -> 5.3405672 | M14: =IF(I14>=1,O14,N14) -> 2.405956 | N14: ='input site'!EV14 -> 2.405956 | Q14: =IF(I14>=1,O14,R14) -> 0.98976222 | R14: ='[5]input site'!CN14 -> 0.98976222 | T14: =Table12[[#This Row],[(Mt CO2 equivalent)]] -> Albania | U14: =VLOOKUP($G14,'NZT data'!$B$3:$F$200,4,FALSE) -> 2110 | V14: =VLOOKUP($G14,'NZT data'!$B$3:$F$200,5,FALSE) | W14: =-IF('LUC NGHGI'!EC4="",MIN('LUC NGHGI'!DW4,0.1),MIN('LUC NGHGI'!EC4,0.1)) -> -0.1 | X14: ='LUC NGHGI'!EC4 -> 1.953267 | Y14: ='LUC NGHGI'!DY4 -> 1.953267 | Z14: ='LUC NGHGI'!DZ4 -> 1.953267 | AA14: =Table12[[#This Row],[2021 emissions]] -> 10.422791 | AB14: ='LUC NGHGI'!DW4 -> 1.9695025 | AC14: =IF(F14="incl",Table12[[#This Row],[GHG emissions incl LULUCF]]-Table12[[#This Row],[LULUCF emis-sions in 20213]],Table12[[#This Row],[GHG emissions incl LULUCF]]) -> 10.422791 | AD14: ='input site'!BS14 -> 5.3405672 | AE14: ='LUC NGHGI'!EH4 -> 2.1375888 | AF14: =IF(F14="incl",Table12[[#This Row],[Current Policies 2030 incl LULUCF]]-Table12[[#This Row],[LULUCF CurPol 2030]],Table12[[#This Row],[Current Policies 2030 incl LULUCF]]) -> 5.3405672 | AG14: =IF(Table12[[#This Row],[Net-zero target status]]<=1,"",IF(Table12[[#This Row],[NZ GHG year]]="","",1000000000*(Table12[[#This Row],[residual LULUCF emissions in 2050]]-Table12[[#This Row],[GHG emissions excl LULUCF]])/(Table12[[#This Row],[NZ GHG year]]-2021)/Table12[[#This Row],[Population]])) | AH14: =IF(Table12[[#This Row],[Peak revised]]="Yes",IF(Table12[[#This Row],[Net-zero target status]]<=1,"",IF(Table12[[#This Row],[NZ GHG year]]="","",1000000000*(Table12[[#This Row],[residual LULUCF emissions in 2050]]-Table12[[#This Row],[GHG emissions excl LULUCF]])/(Table12[[#This Row],[NZ GHG year]]-2021)/Table12[[#This Row],[Population]])),"") | AI14: =MAX(0,(1000000*(Table12[[#This Row],[Current Policies 2030 excl LULUCF]]/2+Table12[[#This Row],[GHG emissions excl LULUCF]]/2)/Table12[[#This Row],[Population]]-$AI$8)*10)*$AI$10 -> 0 | AJ14: =IF(Table12[[#This Row],[Peak revised]]="No",IF(Table12[[#This Row],[Net-zero target status]]<=1,"",IF(Table12[[#This Row],[NZ GHG year]]="","",1000000000*(Table12[[#This Row],[residual LULUCF emissions in 2050]]-Table12[[#This Row],[Current Policies 2030 excl LULUCF]])/(Table12[[#This Row],[NZ GHG year]]-2021)/Table12[[#This Row],[Population]])),"") | AK14: =IF(Table12[[#This Row],[Formule no Peak (2)]]="","",Table12[[#This Row],[Penalty (1)]]+Table12[[#This Row],[Formule no Peak (2)]]) | AL14: =(Table12[[#This Row],[Current Policies 2030 excl LULUCF]]-Table12[[#This Row],[GHG emissions excl LULUCF]])/(2030-2021)/Table12[[#This Row],[GHG emissions excl LULUCF]] -> -0.054178534 | AM14: =IF(Table12[[#This Row],[Net-zero target status]]<=1,"",IF(Table12[[#This Row],[NZ GHG year]]="","",(Table12[[#This Row],[residual LULUCF emissions in 2050]]-Table12[[#This Row],[Current Policies 2030 excl LULUCF]])/(Table12[[#This Row],[NZ GHG year]]-2030)/Table12[[#This Row],[Current Policies 2030 excl LULUCF]])) | AN14: =IF(Table12[[#This Row],[Net-zero target status]]<=1,"",IF(Table12[[#This Row],[NZ GHG year]]="","",(Table12[[#This Row],[residual LULUCF emissions in 2050]]-Table12[[#This Row],[GHG emissions excl LULUCF]])/(Table12[[#This Row],[NZ GHG year]]-2021)/Table12[[#This Row],[GHG emissions excl LULUCF]])) | AO14: =IF(Table12[[#This Row],[Net-zero target status]]<=1,"",IF(Table12[[#This Row],[NZ GHG year]]="","",(Table12[[#This Row],[residual LULUCF emissions in 2050]]-Table12[[#This Row],[2030 conditional NDCs]])/(Table12[[#This Row],[NZ GHG year]]-2030)/Table12[[#This Row],[2030 conditional NDCs]])) | AP14: =MAX('input site'!AH14:AS14) -> 10.670696 | AQ14: =IF(Table12[[#This Row],[Current Policies 2030 incl LULUCF]]>Table12[[#This Row],[Maximum inventory data]],"No","Yes") -> Yes | AR14: =IF(Table12[[#This Row],[Net-zero target status]]>=1.5,Table12[[#This Row],[residual LULUCF emissions in 2050]]/Table12[[#This Row],[GHG emissions excl LULUCF]],"") | AU14: ='input site'!BG14 -> 11.978 | AV14: ='input site'!BH14 -> 11.978 | AW14: =IF(Table12[[#This Row],[2030 unconditional NDCs]]="","",IF(F14="incl",Table12[[#This Row],[2030 unconditional NDCs]]-Table12[[#This Row],[LULUCF NDC uncond]],Table12[[#This Row],[2030 unconditional NDCs]])) | AX14: =IF(Table12[[#This Row],[2030 unconditional NDCs2]]="","",IF(F14="incl",Table12[[#This Row],[2030 unconditional NDCs2]]-Table12[[#This Row],[LULUCF NDC uncond]],Table12[[#This Row],[2030 unconditional NDCs2]])) | AY14: =IF(Table12[[#This Row],[2030 conditional NDCs]]="","",IF(F14="incl",Table12[[#This Row],[2030 conditional NDCs]]-Table12[[#This Row],[LULUCF NDC cond]],Table12[[#This Row],[2030 conditional NDCs]])) -> 11.978 | AZ14: =IF(Table12[[#This Row],[2030 conditional NDCs2]]="","",IF(F14="incl",Table12[[#This Row],[2030 conditional NDCs2]]-Table12[[#This Row],[LULUCF NDC cond]],Table12[[#This Row],[2030 conditional NDCs2]])) -> 11.978 | BA14: =VLOOKUP($G14,'Population90 20'!$C$6:$AU$231,37,FALSE) -> 2866374 | BB14: =VLOOKUP($G14,'Overview GDP (PPP)'!$C$6:$AI$231,33,FALSE) -> 35274375 | BC14: =Table12[[#This Row],[Income]]/Table12[[#This Row],[Population]] -> 12.306271 | BD14: =Table12[[#This Row],[GHG emissions excl LULUCF]]*1000000/Table12[[#This Row],[Population]] -> 3.6362286 | BE14: =VLOOKUP($G14,EGR2023_MASTER!$B$4:$S$38,14,FALSE) -> #N/A | BF14: =VLOOKUP($G14,EGR2023_MASTER!$B$4:$S$38,15,FALSE) -> #N/A | BG14: =VLOOKUP($G14,EGR2023_MASTER!$B$4:$S$38,16,FALSE) -> #N/A | BH14: =IF(AND(BE14="Y",AND(BF14="credible",BG14="Y")),"higher",IF(BG14="Y","lower",IF(AND(BG14="N",OR(BE14="Y",BF14="credible")),"lower","much lower"))) -> #N/A | BI14: =IF(AND($BF14="credible",BG14="Y"),"stronger","weak") -> #N/A | BJ14: =(Table12[[#This Row],[Current Policies 2030 excl LULUCF]]/Table12[[#This Row],[GHG emissions excl LULUCF]])^(1/(2030-2021))-1 -> -0.071603048 | BK14: =IF(Table12[[#This Row],[Net-zero target status]]<=1,"",IF(Table12[[#This Row],[NZ GHG year]]="","",((MAX(Table12[[#This Row],[residual LULUCF emissions in 2050]],0.1)/Table12[[#This Row],[Current Policies 2030 excl LULUCF]])^(1/(Table12[[#This Row],[NZ GHG year]]-2021))-1))) | BL14: =IF(Table12[[#This Row],[Net-zero target status]]<=1,"",IF(Table12[[#This Row],[NZ GHG year]]="","",((MAX(Table12[[#This Row],[residual LULUCF emissions in 2050]],0.1)/Table12[[#This Row],[GHG emissions excl LULUCF]])^(1/(Table12[[#This Row],[NZ GHG year]]-2021))-1))) | BM14: =IF(Table12[[#This Row],[Net-zero target status]]<=1,"",IF(Table12[[#This Row],[NZ GHG year]]="","",((MAX(Table12[[#This Row],[residual LULUCF emissions in 2050]],0.1)/AVERAGE(Table12[[#This Row],[2030 conditional NDCs]:[2030 conditional NDCs2]]))^(1/(Table12[[#This Row],[NZ GHG year]]-2021))-1))) | BR14: Albania | BT14: =IF(Table12[[#This Row],[Reduction rate 2021 to NZ target2]]="","",J14*(1+AN14)^(Table12[[#This Row],[NZ GHG year]]-2021))
A15: 0 | B15: 0 | C15: 12 | D15: 3 | E15: 7 | F15: ='input site'!M15 -> incl | G15: DZA | H15: Algeria | I15: =VLOOKUP($G15,'NZT data'!$B$3:$C$200,2,FALSE) -> 0 | J15: ='input site'!AS15 -> 259.62369 | K15: ='input site'!BS15 -> 258.88165 | L15: =IF(I15>=1,O15,K15) -> 258.88165 | M15: =IF(I15>=1,O15,N15) -> 122.83157 | N15: ='input site'!EV15 -> 122.83157 | Q15: =IF(I15>=1,O15,R15) -> 35.930255 | R15: ='[5]input site'!CN15 -> 35.930255 | T15: =Table12[[#This Row],[(Mt CO2 equivalent)]] -> Algeria | U15: =VLOOKUP($G15,'NZT data'!$B$3:$F$200,4,FALSE) -> 2110 | V15: =VLOOKUP($G15,'NZT data'!$B$3:$F$200,5,FALSE) | W15: =-IF('LUC NGHGI'!EC5="",MIN('LUC NGHGI'!DW5,0.1),MIN('LUC NGHGI'!EC5,0.1)) -> 8.93341 | X15: ='LUC NGHGI'!EC5 -> -8.93341 | Y15: ='LUC NGHGI'!DY5 -> -16 | Z15: ='LUC NGHGI'!DZ5 -> -8 | AA15: =Table12[[#This Row],[2021 emissions]] -> 259.62369 | AB15: ='LUC NGHGI'!DW5 -> -10.657188 | AC15: =IF(F15="incl",Table12[[#This Row],[GHG emissions incl LULUCF]]-Table12[[#This Row],[LULUCF emis-sions in 20213]],Table12[[#This Row],[GHG emissions incl LULUCF]]) -> 270.28088 | AD15: ='input site'!BS15 -> 258.88165 | AE15: ='LUC NGHGI'!EH5 -> -11.303418 | AF15: =IF(F15="incl",Table12[[#This Row],[Current Policies 2030 incl LULUCF]]-Table12[[#This Row],[LULUCF CurPol 2030]],Table12[[#This Row],[Current Policies 2030 incl LULUCF]]) -> 270.18507 | AG15: =IF(Table12[[#This Row],[Net-zero target status]]<=1,"",IF(Table12[[#This Row],[NZ GHG year]]="","",1000000000*(Table12[[#This Row],[residual LULUCF emissions in 2050]]-Table12[[#This Row],[GHG emissions excl LULUCF]])/(Table12[[#This Row],[NZ GHG year]]-2021)/Table12[[#This Row],[Population]])) | AH15: =IF(Table12[[#This Row],[Peak revised]]="Yes",IF(Table12[[#This Row],[Net-zero target status]]<=1,"",IF(Table12[[#This Row],[NZ GHG year]]="","",1000000000*(Table12[[#This Row],[residual LULUCF emissions in 2050]]-Table12[[#This Row],[GHG emissions excl LULUCF]])/(Table12[[#This Row],[NZ GHG year]]-2021)/Table12[[#This Row],[Population]])),"") | AI15: =MAX(0,(1000000*(Table12[[#This Row],[Current Policies 2030 excl LULUCF]]/2+Table12[[#This Row],[GHG emissions excl LULUCF]]/2)/Table12[[#This Row],[Population]]-$AI$8)*10)*$AI$10 -> 0 | AJ15: =IF(Table12[[#This Row],[Peak revised]]="No",IF(Table12[[#This Row],[Net-zero target status]]<=1,"",IF(Table12[[#This Row],[NZ GHG year]]="","",1000000000*(Table12[[#This Row],[residual LULUCF emissions in 2050]]-Table12[[#This Row],[Current Policies 2030 excl LULUCF]])/(Table12[[#This Row],[NZ GHG year]]-2021)/Table12[[#This Row],[Population]])),"") | AK15: =IF(Table12[[#This Row],[Formule no Peak (2)]]="","",Table12[[#This Row],[Penalty (1)]]+Table12[[#This Row],[Formule no Peak (2)]]) | AL15: =(Table12[[#This Row],[Current Policies 2030 excl LULUCF]]-Table12[[#This Row],[GHG emissions excl LULUCF]])/(2030-2021)/Table12[[#This Row],[GHG emissions excl LULUCF]] -> -3.9388357e-05 | AM15: =IF(Table12[[#This Row],[Net-zero target status]]<=1,"",IF(Table12[[#This Row],[NZ GHG year]]="","",(Table12[[#This Row],[residual LULUCF emissions in 2050]]-Table12[[#This Row],[Current Policies 2030 excl LULUCF]])/(Table12[[#This Row],[NZ GHG year]]-2030)/Table12[[#This Row],[Current Policies 2030 excl LULUCF]])) | AN15: =IF(Table12[[#This Row],[Net-zero target status]]<=1,"",IF(Table12[[#This Row],[NZ GHG year]]="","",(Table12[[#This Row],[residual LULUCF emissions in 2050]]-Table12[[#This Row],[GHG emissions excl LULUCF]])/(Table12[[#This Row],[NZ GHG year]]-2021)/Table12[[#This Row],[GHG emissions excl LULUCF]])) | AO15: =IF(Table12[[#This Row],[Net-zero target status]]<=1,"",IF(Table12[[#This Row],[NZ GHG year]]="","",(Table12[[#This Row],[residual LULUCF emissions in 2050]]-Table12[[#This Row],[2030 conditional NDCs]])/(Table12[[#This Row],[NZ GHG year]]-2030)/Table12[[#This Row],[2030 conditional NDCs]])) | AP15: =MAX('input site'!AH15:AS15) -> 267.17547 | AQ15: =IF(Table12[[#This Row],[Current Policies 2030 incl LULUCF]]>Table12[[#This Row],[Maximum inventory data]],"No","Yes") -> Yes | AR15: =IF(Table12[[#This Row],[Net-zero target status]]>=1.5,Table12[[#This Row],[residual LULUCF emissions in 2050]]/Table12[[#This Row],[GHG emissions excl LULUCF]],"") | AS15: ='input site'!BE15 -> 233.7343 | AT15: ='input site'!BF15 -> 233.7343 | AU15: ='input site'!BG15 -> 196.03522 | AV15: ='input site'!BH15 -> 196.03522 | AW15: =IF(Table12[[#This Row],[2030 unconditional NDCs]]="","",IF(F15="incl",Table12[[#This Row],[2030 unconditional NDCs]]-Table12[[#This Row],[LULUCF NDC uncond]],Table12[[#This Row],[2030 unconditional NDCs]])) -> 249.7343 | AX15: =IF(Table12[[#This Row],[2030 unconditional NDCs2]]="","",IF(F15="incl",Table12[[#This Row],[2030 unconditional NDCs2]]-Table12[[#This Row],[LULUCF NDC uncond]],Table12[[#This Row],[2030 unconditional NDCs2]])) -> 249.7343 | AY15: =IF(Table12[[#This Row],[2030 conditional NDCs]]="","",IF(F15="incl",Table12[[#This Row],[2030 conditional NDCs]]-Table12[[#This Row],[LULUCF NDC cond]],Table12[[#This Row],[2030 conditional NDCs]])) -> 204.03522 | AZ15: =IF(Table12[[#This Row],[2030 conditional NDCs2]]="","",IF(F15="incl",Table12[[#This Row],[2030 conditional NDCs2]]-Table12[[#This Row],[LULUCF NDC cond]],Table12[[#This Row],[2030 conditional NDCs2]])) -> 204.03522 | BA15: =VLOOKUP($G15,'Population90 20'!$C$6:$AU$231,37,FALSE) -> 45350148 | BB15: =VLOOKUP($G15,'Overview GDP (PPP)'!$C$6:$AI$231,33,FALSE) -> 5.8638961e+08 | BC15: =Table12[[#This Row],[Income]]/Table12[[#This Row],[Population]] -> 12.930269 | BD15: =Table12[[#This Row],[GHG emissions excl LULUCF]]*1000000/Table12[[#This Row],[Population]] -> 5.9598677 | BE15: =VLOOKUP($G15,EGR2023_MASTER!$B$4:$S$38,14,FALSE) -> #N/A | BF15: =VLOOKUP($G15,EGR2023_MASTER!$B$4:$S$38,15,FALSE) -> #N/A | BG15: =VLOOKUP($G15,EGR2023_MASTER!$B$4:$S$38,16,FALSE) -> #N/A | BH15: =IF(AND(BE15="Y",AND(BF15="credible",BG15="Y")),"higher",IF(BG15="Y","lower",IF(AND(BG15="N",OR(BE15="Y",BF15="credible")),"lower","much lower"))) -> #N/A | BI15: =IF(AND($BF15="credible",BG15="Y"),"stronger","weak") -> #N/A | BJ15: =(Table12[[#This Row],[Current Policies 2030 excl LULUCF]]/Table12[[#This Row],[GHG emissions excl LULUCF]])^(1/(2030-2021))-1 -> -3.9394565e-05 | BK15: =IF(Table12[[#This Row],[Net-zero target status]]<=1,"",IF(Table12[[#This Row],[NZ GHG year]]="","",((MAX(Table12[[#This Row],[residual LULUCF emissions in 2050]],0.1)/Table12[[#This Row],[Current Policies 2030 excl LULUCF]])^(1/(Table12[[#This Row],[NZ GHG year]]-2021))-1))) | BL15: =IF(Table12[[#This Row],[Net-zero target status]]<=1,"",IF(Table12[[#This Row],[NZ GHG year]]="","",((MAX(Table12[[#This Row],[residual LULUCF emissions in 2050]],0.1)/Table12[[#This Row],[GHG emissions excl LULUCF]])^(1/(Table12[[#This Row],[NZ GHG year]]-2021))-1))) | BM15: =IF(Table12[[#This Row],[Net-zero target status]]<=1,"",IF(Table12[[#This Row],[NZ GHG year]]="","",((MAX(Table12[[#This Row],[residual LULUCF emissions in 2050]],0.1)/AVERAGE(Table12[[#This Row],[2030 conditional NDCs]:[2030 conditional NDCs2]]))^(1/(Table12[[#This Row],[NZ GHG year]]-2021))-1))) | BR15: Algeria | BT15: =IF(Table12[[#This Row],[Reduction rate 2021 to NZ target2]]="","",J15*(1+AN15)^(Table12[[#This Row],[NZ GHG year]]-2021))
A16: 0 | B16: 0 | C16: 16 | D16: 4 | E16: 24 | F16: ='input site'!M16 -> excl | G16: ASM | H16: American Samoa | I16: 0 | J16: ='input site'!AS16 -> 0 | K16: ='input site'!BS16 -> 0 | L16: =IF(I16>=1,O16,K16) -> 0 | M16: =IF(I16>=1,O16,N16) -> 0 | N16: ='input site'!EV16 -> 0 | Q16: =IF(I16>=1,O16,R16) -> 0.0062334932 | R16: ='[5]input site'!CN16 -> 0.0062334932 | T16: =Table12[[#This Row],[(Mt CO2 equivalent)]] -> American Samoa | U16: 2100 | V16: 2100 | W16: =-IF('LUC NGHGI'!EC6="",MIN('LUC NGHGI'!DW6,0.1),MIN('LUC NGHGI'!EC6,0.1)) -> 0.757 | X16: ='LUC NGHGI'!EC6 -> -0.757 | Y16: ='LUC NGHGI'!DY6 -> -0.757 | Z16: ='LUC NGHGI'!DZ6 -> -0.757 | AA16: =Table12[[#This Row],[2021 emissions]] -> 0 | AB16: ='LUC NGHGI'!DW6 -> -0.63783226 | AC16: =IF(F16="incl",Table12[[#This Row],[GHG emissions incl LULUCF]]-Table12[[#This Row],[LULUCF emis-sions in 20213]],Table12[[#This Row],[GHG emissions incl LULUCF]]) -> 0 | AD16: ='input site'!BS16 -> 0 | AE16: ='LUC NGHGI'!EH6 -> -0.70635243 | AF16: =IF(F16="incl",Table12[[#This Row],[Current Policies 2030 incl LULUCF]]-Table12[[#This Row],[LULUCF CurPol 2030]],Table12[[#This Row],[Current Policies 2030 incl LULUCF]]) -> 0 | AG16: =IF(Table12[[#This Row],[Net-zero target status]]<=1,"",IF(Table12[[#This Row],[NZ GHG year]]="","",1000000000*(Table12[[#This Row],[residual LULUCF emissions in 2050]]-Table12[[#This Row],[GHG emissions excl LULUCF]])/(Table12[[#This Row],[NZ GHG year]]-2021)/Table12[[#This Row],[Population]])) | AH16: =IF(Table12[[#This Row],[Peak revised]]="Yes",IF(Table12[[#This Row],[Net-zero target status]]<=1,"",IF(Table12[[#This Row],[NZ GHG year]]="","",1000000000*(Table12[[#This Row],[residual LULUCF emissions in 2050]]-Table12[[#This Row],[GHG emissions excl LULUCF]])/(Table12[[#This Row],[NZ GHG year]]-2021)/Table12[[#This Row],[Population]])),"") | AI16: =MAX(0,(1000000*(Table12[[#This Row],[Current Policies 2030 excl LULUCF]]/2+Table12[[#This Row],[GHG emissions excl LULUCF]]/2)/Table12[[#This Row],[Population]]-$AI$8)*10)*$AI$10 -> 0 | AJ16: =IF(Table12[[#This Row],[Peak revised]]="No",IF(Table12[[#This Row],[Net-zero target status]]<=1,"",IF(Table12[[#This Row],[NZ GHG year]]="","",1000000000*(Table12[[#This Row],[residual LULUCF emissions in 2050]]-Table12[[#This Row],[Current Policies 2030 excl LULUCF]])/(Table12[[#This Row],[NZ GHG year]]-2021)/Table12[[#This Row],[Population]])),"") | AK16: =IF(Table12[[#This Row],[Formule no Peak (2)]]="","",Table12[[#This Row],[Penalty (1)]]+Table12[[#This Row],[Formule no Peak (2)]]) | AL16: =(Table12[[#This Row],[Current Policies 2030 excl LULUCF]]-Table12[[#This Row],[GHG emissions excl LULUCF]])/(2030-2021)/Table12[[#This Row],[GHG emissions excl LULUCF]] -> #DIV/0! | AM16: =IF(Table12[[#This Row],[Net-zero target status]]<=1,"",IF(Table12[[#This Row],[NZ GHG year]]="","",(Table12[[#This Row],[residual LULUCF emissions in 2050]]-Table12[[#This Row],[Current Policies 2030 excl LULUCF]])/(Table12[[#This Row],[NZ GHG year]]-2030)/Table12[[#This Row],[Current Policies 2030 excl LULUCF]])) | AN16: =IF(Table12[[#This Row],[Net-zero target status]]<=1,"",IF(Table12[[#This Row],[NZ GHG year]]="","",(Table12[[#This Row],[residual LULUCF emissions in 2050]]-Table12[[#This Row],[GHG emissions excl LULUCF]])/(Table12[[#This Row],[NZ GHG year]]-2021)/Table12[[#This Row],[GHG emissions excl LULUCF]])) | AO16: =IF(Table12[[#This Row],[Net-zero target status]]<=1,"",IF(Table12[[#This Row],[NZ GHG year]]="","",(Table12[[#This Row],[residual LULUCF emissions in 2050]]-Table12[[#This Row],[2030 conditional NDCs]])/(Table12[[#This Row],[NZ GHG year]]-2030)/Table12[[#This Row],[2030 conditional NDCs]])) | AP16: =MAX('input site'!AH16:AS16) -> 0 | AQ16: =IF(Table12[[#This Row],[Current Policies 2030 incl LULUCF]]>Table12[[#This Row],[Maximum inventory data]],"No","Yes") -> Yes | AR16: =IF(Table12[[#This Row],[Net-zero target status]]>=1.5,Table12[[#This Row],[residual LULUCF emissions in 2050]]/Table12[[#This Row],[GHG emissions excl LULUCF]],"") | AW16: =IF(Table12[[#This Row],[2030 unconditional NDCs]]="","",IF(F16="incl",Table12[[#This Row],[2030 unconditional NDCs]]-Table12[[#This Row],[LULUCF NDC uncond]],Table12[[#This Row],[2030 unconditional NDCs]])) | AX16: =IF(Table12[[#This Row],[2030 unconditional NDCs2]]="","",IF(F16="incl",Table12[[#This Row],[2030 unconditional NDCs2]]-Table12[[#This Row],[LULUCF NDC uncond]],Table12[[#This Row],[2030 unconditional NDCs2]])) | AY16: =IF(Table12[[#This Row],[2030 conditional NDCs]]="","",IF(F16="incl",Table12[[#This Row],[2030 conditional NDCs]]-Table12[[#This Row],[LULUCF NDC cond]],Table12[[#This Row],[2030 conditional NDCs]])) | AZ16: =IF(Table12[[#This Row],[2030 conditional NDCs2]]="","",IF(F16="incl",Table12[[#This Row],[2030 conditional NDCs2]]-Table12[[#This Row],[LULUCF NDC cond]],Table12[[#This Row],[2030 conditional NDCs2]])) | BA16: =VLOOKUP($G16,'Population90 20'!$C$6:$AU$231,37,FALSE) -> 55030 | BB16: =VLOOKUP($G16,'Overview GDP (PPP)'!$C$6:$AI$231,33,FALSE) -> 486064.72 | BC16: =Table12[[#This Row],[Income]]/Table12[[#This Row],[Population]] -> 8.8327225 | BD16: =Table12[[#This Row],[GHG emissions excl LULUCF]]*1000000/Table12[[#This Row],[Population]] -> 0 | BE16: =VLOOKUP($G16,EGR2023_MASTER!$B$4:$S$38,14,FALSE) -> #N/A | BF16: =VLOOKUP($G16,EGR2023_MASTER!$B$4:$S$38,15,FALSE) -> #N/A | BG16: =VLOOKUP($G16,EGR2023_MASTER!$B$4:$S$38,16,FALSE) -> #N/A | BH16: =IF(AND(BE16="Y",AND(BF16="credible",BG16="Y")),"higher",IF(BG16="Y","lower",IF(AND(BG16="N",OR(BE16="Y",BF16="credible")),"lower","much lower"))) -> #N/A | BI16: =IF(AND($BF16="credible",BG16="Y"),"stronger","weak") -> #N/A | BJ16: =(Table12[[#This Row],[Current Policies 2030 excl LULUCF]]/Table12[[#This Row],[GHG emissions excl LULUCF]])^(1/(2030-2021))-1 -> #DIV/0! | BK16: =IF(Table12[[#This Row],[Net-zero target status]]<=1,"",IF(Table12[[#This Row],[NZ GHG year]]="","",((MAX(Table12[[#This Row],[residual LULUCF emissions in 2050]],0.1)/Table12[[#This Row],[Current Policies 2030 excl LULUCF]])^(1/(Table12[[#This Row],[NZ GHG year]]-2021))-1))) | BL16: =IF(Table12[[#This Row],[Net-zero target status]]<=1,"",IF(Table12[[#This Row],[NZ GHG year]]="","",((MAX(Table12[[#This Row],[residual LULUCF emissions in 2050]],0.1)/Table12[[#This Row],[GHG emissions excl LULUCF]])^(1/(Table12[[#This Row],[NZ GHG year]]-2021))-1))) | BM16: =IF(Table12[[#This Row],[Net-zero target status]]<=1,"",IF(Table12[[#This Row],[NZ GHG year]]="","",((MAX(Table12[[#This Row],[residual LULUCF emissions in 2050]],0.1)/AVERAGE(Table12[[#This Row],[2030 conditional NDCs]:[2030 conditional NDCs2]]))^(1/(Table12[[#This Row],[NZ GHG year]]-2021))-1))) | BR16: American Samoa | BT16: =IF(Table12[[#This Row],[Reduction rate 2021 to NZ target2]]="","",J16*(1+AN16)^(Table12[[#This Row],[NZ GHG year]]-2021))
